Workbook

Sheet Set up Report
A1: You should only change the parts highlighted in Yellow.
E4: Oak Learning Zone
A5: Hazel Learning Zone | B5: this will change some colour elements in the report | E5: Beech Learning Zone
A6: July 2025 | E6: Willow Learning Zone
A7: Mr McLean | B7: teacher's name | E7: Acer Learning Zone
E8: Maple Learning Zone
A9: Annual Report to Families | E9: Hazel Learning Zone
A10: Dear Families, | E10: Elm Learning Zone
A12: It’s a pleasure to share this annual report celebrating
A13: journey at WFA for 2024–25. This year has been rich in learning and connection—from celebrating Diwali and Eid to deepening inclusive practice through Black History Month and anti-prejudice work. We’ve also strengthened wellbeing support with a dedicated Mental Health Practitioner, and learners have thrived through science, oracy, and leadership experiences. The report highlights
A14: achievements and next steps—I hope it offers a meaningful opportunity to celebrate their progress.
A16: ="If you have any questions, please don’t hesitate to contact us to arrange a conversation with "&A7&"." -> If you have any questions, please don’t hesitate to contact us to arrange a conversation with Mr McLean.
A17: Warm regards,
A18: Charlotte Black (Principal)
A20: Learner's attainment is based on the expectations for their year group and is assessed in the following ways:
A21: GD - Greater Depth | B21: Learners who have achieved the age-related standard for their year group and in some aspects have been learning at greater depth.
A22: O - On Track | B22: Learners who have achieved the age-related standard.
A23: Y - Yet to be on track | B23: Learners who have not yet achieved the age-related standard and are having additional support and provision to develop their skills.
A24: A - At an earlier stage | B24: Learners who are below the age-related standard for their year group and still have gaps within the curriculum from a previous year group. For example, A-2 means the learner is working within the Year 2 curriculum.
A25: (A - Year Group)
A27: as an Author and a Mathematician
A29: Being a reader
A30: Being a writer
A31: Being a mathematician
A33: My time in
A35: as a learner:
A39: ​ | B39: Attendance​ | C39: Punctuality​
A40: Exceptional​ | B40: Attendance is 99% or higher​ | C40: Always in school on time​
A41: Expected​ | B41: Attendance is 96% or higher​ | C41: Very rarely late to school​
A42: Below Expected​ | B42: Attendance falls below 96%​ | C42: Frequently late to school​
A43: Cause for Concern​ | B43: Attendance is below 90%​ | C43: Persistently late to school​
A45: ​ | B45: Attendance​ | C45: Punctuality​ (late #)
A46: Exceptional​ | B46: 99 | C46: 0 | D46: A
A47: Expected​ | B47: 96 | C47: 2 | D47: B
A48: Below Expected​ | B48: 96 | C48: 7 | D48: C
A49: Cause for Concern​ | B49: 90 | C49: 8 | D49: D
A51: Enquiries
A53: Use this page to help your child remember the enquiries they have learnt about this year.
A75: As we approach the end of the academic year, I am pleased to share with you
A76: annual report for 2022-23. This gives an overview of
...

Sheet Data
B1: Copy Paste from DOOYA | E1: Copy Paste from DOOYA | H1: copy-paste from Welcome Zone Report | J1: copy-paste from Welcome Zone Report
A2: ID | B2: First Name | C2: Last Name | D2: Full Name | E2: R | F2: W | G2: M | H2: Attendance | I2: Att Code | J2: Punctuality (Lates) # | K2: Punc Code | L2: Reader Teacher comments | M2: Writer Teacher comments | N2: Mathematician Teacher comments | O2: 21st C learner Teacher comments | P2: Rights and Responsibilities Teacher comments | Q2: Pupil Voice
A3: ch01 | B3: Seyi | C3: Adeniji | D3: Seyi Adeniji | E3: D | F3: O | G3: O | H3: 99 | I3: =IF(H3>='Set up Report'!$B$46,"A",IF(H3>='Set up Report'!$B$47,"B",IF(H3<'Set up Report'!$B$49,"D","C"))) -> A | J3: 1 | K3: =IF(AND(J3='Set up Report'!$C$46),"A",IF(AND(J3<='Set up Report'!$C$47),"B",IF(AND(J3<='Set up Report'!$C$48),"C",IF(AND(J3>'Set up Report'!$C$48),"D")))) -> B
A4: ch02 | B4: Amal | C4: Al Arab | D4: Amal Al Arab | E4: D | F4: D | G4: D | H4: 99 | I4: =IF(H4>='Set up Report'!$B$46,"A",IF(H4>='Set up Report'!$B$47,"B",IF(H4<'Set up Report'!$B$49,"D","C"))) -> A | J4: 1 | K4: =IF(AND(J4='Set up Report'!$C$46),"A",IF(AND(J4<='Set up Report'!$C$47),"B",IF(AND(J4<='Set up Report'!$C$48),"C",IF(AND(J4>'Set up Report'!$C$48),"D")))) -> B
A5: ch03 | B5: Aseenat | C5: Al Hlayel | D5: Aseenat Al Hlayel | E5: O | F5: A Y4 | G5: Y | H5: 99 | I5: =IF(H5>='Set up Report'!$B$46,"A",IF(H5>='Set up Report'!$B$47,"B",IF(H5<'Set up Report'!$B$49,"D","C"))) -> A | J5: 1 | K5: =IF(AND(J5='Set up Report'!$C$46),"A",IF(AND(J5<='Set up Report'!$C$47),"B",IF(AND(J5<='Set up Report'!$C$48),"C",IF(AND(J5>'Set up Report'!$C$48),"D")))) -> B
A6: ch04 | B6: Zayn | C6: Alshehri | D6: Zayn Alshehri | E6: O | F6: O | G6: O | H6: 99 | I6: =IF(H6>='Set up Report'!$B$46,"A",IF(H6>='Set up Report'!$B$47,"B",IF(H6<'Set up Report'!$B$49,"D","C"))) -> A | J6: 1 | K6: =IF(AND(J6='Set up Report'!$C$46),"A",IF(AND(J6<='Set up Report'!$C$47),"B",IF(AND(J6<='Set up Report'!$C$48),"C",IF(AND(J6>'Set up Report'!$C$48),"D")))) -> B
A7: ch05 | B7: Marcus | C7: Andrusyszyn | D7: Marcus Andrusyszyn | E7: D | F7: D | G7: D | H7: 99 | I7: =IF(H7>='Set up Report'!$B$46,"A",IF(H7>='Set up Report'!$B$47,"B",IF(H7<'Set up Report'!$B$49,"D","C"))) -> A | J7: 1 | K7: =IF(AND(J7='Set up Report'!$C$46),"A",IF(AND(J7<='Set up Report'!$C$47),"B",IF(AND(J7<='Set up Report'!$C$48),"C",IF(AND(J7>'Set up Report'!$C$48),"D")))) -> B
A8: ch06 | B8: Jenson | C8: Anniss | D8: Jenson Anniss | E8: O | F8: O | G8: O | H8: 99 | I8: =IF(H8>='Set up Report'!$B$46,"A",IF(H8>='Set up Report'!$B$47,"B",IF(H8<'Set up Report'!$B$49,"D","C"))) -> A | J8: 1 | K8: =IF(AND(J8='Set up Report'!$C$46),"A",IF(AND(J8<='Set up Report'!$C$47),"B",IF(AND(J8<='Set up Report'!$C$48),"C",IF(AND(J8>'Set up Report'!$C$48),"D")))) -> B
A9: ch07 | B9: Varun | C9: Arsada | D9: Varun Arsada | E9: D | F9: D | G9: D | H9: 99 | I9: =IF(H9>='Set up Report'!$B$46,"A",IF(H9>='Set up Report'!$B$47,"B",IF(H9<'Set up Report'!$B$49,"D","C"))) -> A | J9: 1 | K9: =IF(AND(J9='Set up Report'!$C$46),"A",IF(AND(J9<='Set up Report'!$C$47),"B",IF(AND(J9<='Set up Report'!$C$48),"C",IF(AND(J9>'Set up Report'!$C$48),"D")))) -> B
A10: ch08 | B10: Eleftherios | C10: Chatzinathanail | D10: Eleftherios Chatzinathanail | E10: O | F10: O | G10: O | H10: 99 | I10: =IF(H10>='Set up Report'!$B$46,"A",IF(H10>='Set up Report'!$B$47,"B",IF(H10<'Set up Report'!$B$49,"D","C"))) -> A | J10: 1 | K10: =IF(AND(J10='Set up Report'!$C$46),"A",IF(AND(J10<='Set up Report'!$C$47),"B",IF(AND(J10<='Set up Report'!$C$48),"C",IF(AND(J10>'Set up Report'!$C$48),"D")))) -> B
A11: ch09 | B11: Xavier | C11: Cheng | D11: Xavier Cheng | E11: D | F11: O | G11: D | H11: 99 | I11: =IF(H11>='Set up Report'!$B$46,"A",IF(H11>='Set up Report'!$B$47,"B",IF(H11<'Set up Report'!$B$49,"D","C"))) -> A | J11: 1 | K11: =IF(AND(J11='Set up Report'!$C$46),"A",IF(AND(J11<='Set up Report'!$C$47),"B",IF(AND(J11<='Set up Report'!$C$48),"C",IF(AND(J11>'Set up Report'!$C$48),"D")))) -> B
A12: ch10 | B12: Isla | C12: Clark | D12: Isla Clark | E12: O | F12: O | G12: O | H12: 99 | I12: =IF(H12>='Set up Report'!$B$46,"A",IF(H12>='Set up Report'!$B$47,"B",IF(H12<'Set up Report'!$B$49,"D","C"))) -> A | J12: 1 | K12: =IF(AND(J12='Set up Report'!$C$46),"A",IF(AND(J12<='Set up Report'!$C$47),"B",IF(AND(J12<='Set up Report'!$C$48),"C",IF(AND(J12>'Set up Report'!$C$48),"D")))) -> B
A13: ch11 | B13: Ronnie | C13: Coles | D13: Ronnie Coles | E13: O | F13: O | G13: Y | H13: 99 | I13: =IF(H13>='Set up Report'!$B$46,"A",IF(H13>='Set up Report'!$B$47,"B",IF(H13<'Set up Report'!$B$49,"D","C"))) -> A | J13: 1 | K13: =IF(AND(J13='Set up Report'!$C$46),"A",IF(AND(J13<='Set up Report'!$C$47),"B",IF(AND(J13<='Set up Report'!$C$48),"C",IF(AND(J13>'Set up Report'!$C$48),"D")))) -> B
A14: ch12 | B14: Evie | C14: Druce | D14: Evie Druce | E14: D | F14: D | G14: O | H14: 99 | I14: =IF(H14>='Set up Report'!$B$46,"A",IF(H14>='Set up Report'!$B$47,"B",IF(H14<'Set up Report'!$B$49,"D","C"))) -> A | J14: 1 | K14: =IF(AND(J14='Set up Report'!$C$46),"A",IF(AND(J14<='Set up Report'!$C$47),"B",IF(AND(J14<='Set up Report'!$C$48),"C",IF(AND(J14>'Set up Report'!$C$48),"D")))) -> B
... A33: ch31 | B33: FN31 | C33: LN31 | D33: FN31 LN31 | E33: O | F33: O | G33: O | H33: 99 | I33: =IF(H33>='Set up Report'!$B$46,"A",IF(H33>='Set up Report'!$B$47,"B",IF(H33<'Set up Report'!$B$49,"D","C"))) -> A | J33: 1 | K33: =IF(AND(J33='Set up Report'!$C$46),"A",IF(AND(J33<='Set up Report'!$C$47),"B",IF(AND(J33<='Set up Report'!$C$48),"C",IF(AND(J33>'Set up Report'!$C$48),"D")))) -> B
